ERROR:ex:Error!
Traceback (most recent call last):
  File "d:\Python\Scripts\log.py", line 16, in <module>
    raise RuntimeError
RuntimeError
